<?xml version="1.0"?>
<robot name="leader_car">
  <link name="base_link">
    <visual><geometry><box size="0.8 0.5 0.3"/></geometry><material name="blue"><color rgba="0 0 1 1"/></material></visual>
    <collision><geometry><box size="0.8 0.5 0.3"/></geometry></collision>
    <inertial><mass value="10.0"/><inertia ixx="0.5" ixy="0" ixz="0" iyy="0.5" iyz="0" izz="0.5"/></inertial>
  </link>

  <link name="left_wheel">
    <visual><geometry><cylinder length="0.1" radius="0.15"/></geometry><material name="black"><color rgba="0 0 0 1"/></material></visual>
    <collision><geometry><cylinder length="0.1" radius="0.15"/></geometry></collision>
    <inertial><mass value="1.0"/><inertia ixx="0.01" ixy="0" ixz="0" iyy="0.01" iyz="0" izz="0.01"/></inertial>
  </link>
  <joint name="joint_left" type="continuous">
    <parent link="base_link"/><child link="left_wheel"/>
    <origin xyz="0.2 0.3 -0.1" rpy="-1.5708 0 0"/><axis xyz="0 0 1"/>
  </joint>

  <link name="right_wheel">
    <visual><geometry><cylinder length="0.1" radius="0.15"/></geometry><material name="black"/></visual>
    <collision><geometry><cylinder length="0.1" radius="0.15"/></geometry></collision>
    <inertial><mass value="1.0"/><inertia ixx="0.01" ixy="0" ixz="0" iyy="0.01" iyz="0" izz="0.01"/></inertial>
  </link>
  <joint name="joint_right" type="continuous">
    <parent link="base_link"/><child link="right_wheel"/>
    <origin xyz="0.2 -0.3 -0.1" rpy="-1.5708 0 0"/><axis xyz="0 0 1"/>
  </joint>

  <link name="caster">
    <visual><geometry><sphere radius="0.05"/></geometry></visual>
    <collision><geometry><sphere radius="0.05"/></geometry></collision>
    <inertial><mass value="0.5"/><inertia ixx="0.001" ixy="0" ixz="0" iyy="0.001" iyz="0" izz="0.001"/></inertial>
  </link>
  <joint name="joint_caster" type="fixed"><parent link="base_link"/><child link="caster"/><origin xyz="-0.3 0 -0.2"/></joint>

  <gazebo reference="caster"><mu1 value="0.001"/><mu2 value="0.001"/></gazebo>

  <gazebo>
    <plugin name="differential_drive_controller" filename="libgazebo_ros_diff_drive.so">
      <robotNamespace>/leader</robotNamespace>
      <leftJoint>joint_left</leftJoint>
      <rightJoint>joint_right</rightJoint>
      <wheelSeparation>0.6</wheelSeparation>
      <wheelDiameter>0.3</wheelDiameter>
      <wheelTorque>100</wheelTorque> <commandTopic>cmd_vel</commandTopic>
      <odometryTopic>odom</odometryTopic>
      <robotBaseFrame>base_link</robotBaseFrame>
    </plugin>
  </gazebo>
</robot>
